<?xml version="1.0" ?>
<robot name="tdofrobotarm" xmlns:xacro="http://www.ros.org/wiki/xacro">

<xacro:include filename="$(find tdofrobotarm_description)/urdf/materials.xacro" />
<xacro:include filename="$(find tdofrobotarm_description)/urdf/tdofrobotarm.trans" />
<xacro:include filename="$(find tdofrobotarm_description)/urdf/tdofrobotarm.gazebo" />
<link name="base_link">
  <inertial>
    <origin xyz="-1.5131464107709274e-17 -7.565732053854637e-18 0.01669022341463877" rpy="0 0 0"/>
    <mass value="2.359168074581756"/>
    <inertia ixx="0.001913" iyy="0.001913" izz="0.003248" ixy="-0.0" iyz="-0.0" ixz="-0.0"/>
  </inertial>
  <visual>
    <origin xyz="0 0 0" rpy="0 0 0"/>
    <geometry>
      <mesh filename="package://tdofrobotarm_description/meshes/base_link.stl" scale="0.001 0.001 0.001"/>
    </geometry>
    <material name="steel_satin"/>
  </visual>
  <collision>
    <origin xyz="0 0 0" rpy="0 0 0"/>
    <geometry>
      <mesh filename="package://tdofrobotarm_description/meshes/base_link.stl" scale="0.001 0.001 0.001"/>
    </geometry>
  </collision>
</link>

<link name="link1_v3_1">
  <inertial>
    <origin xyz="2.9265010934662256e-15 1.2383830102118854e-16 0.013727359835796218" rpy="0 0 0"/>
    <mass value="0.44267396683570365"/>
    <inertia ixx="0.000161" iyy="0.000142" izz="0.000219" ixy="1e-06" iyz="-0.0" ixz="-0.0"/>
  </inertial>
  <visual>
    <origin xyz="-0.0 -0.0 -0.04" rpy="0 0 0"/>
    <geometry>
      <mesh filename="package://tdofrobotarm_description/meshes/link1_v3_1.stl" scale="0.001 0.001 0.001"/>
    </geometry>
    <material name="steel_satin"/>
  </visual>
  <collision>
    <origin xyz="-0.0 -0.0 -0.04" rpy="0 0 0"/>
    <geometry>
      <mesh filename="package://tdofrobotarm_description/meshes/link1_v3_1.stl" scale="0.001 0.001 0.001"/>
    </geometry>
  </collision>
</link>

<link name="link2_v1_1">
  <inertial>
    <origin xyz="0.037864686698214495 0.011545950362599429 0.03213938048431217" rpy="0 0 0"/>
    <mass value="0.2786576290786893"/>
    <inertia ixx="0.000156" iyy="0.000363" izz="0.000212" ixy="-8e-06" iyz="-6e-06" ixz="-0.000158"/>
  </inertial>
  <visual>
    <origin xyz="-0.000406 0.009992 -0.07" rpy="0 0 0"/>
    <geometry>
      <mesh filename="package://tdofrobotarm_description/meshes/link2_v1_1.stl" scale="0.001 0.001 0.001"/>
    </geometry>
    <material name="steel_satin"/>
  </visual>
  <collision>
    <origin xyz="-0.000406 0.009992 -0.07" rpy="0 0 0"/>
    <geometry>
      <mesh filename="package://tdofrobotarm_description/meshes/link2_v1_1.stl" scale="0.001 0.001 0.001"/>
    </geometry>
  </collision>
</link>

<link name="end_effector_v3_1">
  <inertial>
    <origin xyz="0.04112904397153967 -0.003334304829311174 -0.025739056462857818" rpy="0 0 0"/>
    <mass value="0.5162553038394755"/>
    <inertia ixx="0.000161" iyy="0.000354" izz="0.000282" ixy="-8e-06" iyz="5e-06" ixz="0.000126"/>
  </inertial>
  <visual>
    <origin xyz="-0.076339 -0.008104 -0.134279" rpy="0 0 0"/>
    <geometry>
      <mesh filename="package://tdofrobotarm_description/meshes/end_effector_v3_1.stl" scale="0.001 0.001 0.001"/>
    </geometry>
    <material name="steel_satin"/>
  </visual>
  <collision>
    <origin xyz="-0.076339 -0.008104 -0.134279" rpy="0 0 0"/>
    <geometry>
      <mesh filename="package://tdofrobotarm_description/meshes/end_effector_v3_1.stl" scale="0.001 0.001 0.001"/>
    </geometry>
  </collision>
</link>

<joint name="Rev1" type="continuous">
  <origin xyz="0.0 0.0 0.04" rpy="0 0 0"/>
  <parent link="base_link"/>
  <child link="link1_v3_1"/>
  <axis xyz="0.0 0.0 1.0"/>
</joint>

<joint name="Rev2" type="revolute">
  <origin xyz="0.000406 -0.009992 0.03" rpy="0 0 0"/>
  <parent link="link1_v3_1"/>
  <child link="link2_v1_1"/>
  <axis xyz="0.040571 -0.999177 -0.0"/>
  <limit upper="2.443461" lower="0.0" effort="100" velocity="100"/>
</joint>

<joint name="Rev3" type="revolute">
  <origin xyz="0.075933 0.018096 0.064279" rpy="0 0 0"/>
  <parent link="link2_v1_1"/>
  <child link="end_effector_v3_1"/>
  <axis xyz="-0.040571 0.999177 0.0"/>
  <limit upper="6.283185" lower="3.141593" effort="100" velocity="100"/>
</joint>

</robot>
