<?xml version="1.0" ?>
<robot name="twodofrobotarm" xmlns:xacro="http://www.ros.org/wiki/xacro">

<xacro:include filename="$(find twodofrobotarm_description)/urdf/materials.xacro" />
<xacro:include filename="$(find twodofrobotarm_description)/urdf/twodofrobotarm.trans" />
<xacro:include filename="$(find twodofrobotarm_description)/urdf/twodofrobotarm.gazebo" />
<link name="base_link">
  <inertial>
    <origin xyz="-1.5131464107709274e-17 -7.565732053854637e-18 0.01669022341463877" rpy="0 0 0"/>
    <mass value="2.359168074581756"/>
    <inertia ixx="0.001913" iyy="0.001913" izz="0.003248" ixy="-0.0" iyz="-0.0" ixz="-0.0"/>
  </inertial>
  <visual>
    <origin xyz="0 0 0" rpy="0 0 0"/>
    <geometry>
      <mesh filename="package://twodofrobotarm_description/meshes/base_link.stl" scale="0.001 0.001 0.001"/>
    </geometry>
    <material name="steel_satin"/>
  </visual>
  <collision>
    <origin xyz="0 0 0" rpy="0 0 0"/>
    <geometry>
      <mesh filename="package://twodofrobotarm_description/meshes/base_link.stl" scale="0.001 0.001 0.001"/>
    </geometry>
  </collision>
</link>

<link name="link1_v3_1">
  <inertial>
    <origin xyz="2.9107983085076832e-15 3.270648008693948e-16 0.013727359835796218" rpy="0 0 0"/>
    <mass value="0.44267396683570365"/>
    <inertia ixx="0.000161" iyy="0.000142" izz="0.000219" ixy="2e-06" iyz="-0.0" ixz="-0.0"/>
  </inertial>
  <visual>
    <origin xyz="-0.0 -0.0 -0.04" rpy="0 0 0"/>
    <geometry>
      <mesh filename="package://twodofrobotarm_description/meshes/link1_v3_1.stl" scale="0.001 0.001 0.001"/>
    </geometry>
    <material name="steel_satin"/>
  </visual>
  <collision>
    <origin xyz="-0.0 -0.0 -0.04" rpy="0 0 0"/>
    <geometry>
      <mesh filename="package://twodofrobotarm_description/meshes/link1_v3_1.stl" scale="0.001 0.001 0.001"/>
    </geometry>
  </collision>
</link>

<link name="link2_v1_1">
  <inertial>
    <origin xyz="0.045599606633629344 0.015106426260815079 0.017101007166275495" rpy="0 0 0"/>
    <mass value="0.2786576290786893"/>
    <inertia ixx="6.4e-05" iyy="0.00036" izz="0.000307" ixy="-3.3e-05" iyz="-1.1e-05" ixz="-0.000103"/>
  </inertial>
  <visual>
    <origin xyz="-0.0011 0.009939 -0.07" rpy="0 0 0"/>
    <geometry>
      <mesh filename="package://twodofrobotarm_description/meshes/link2_v1_1.stl" scale="0.001 0.001 0.001"/>
    </geometry>
    <material name="steel_satin"/>
  </visual>
  <collision>
    <origin xyz="-0.0011 0.009939 -0.07" rpy="0 0 0"/>
    <geometry>
      <mesh filename="package://twodofrobotarm_description/meshes/link2_v1_1.stl" scale="0.001 0.001 0.001"/>
    </geometry>
  </collision>
</link>

<link name="end_effector_v2_1">
  <inertial>
    <origin xyz="0.02861005886872932 -0.0018652565919647854 -0.036322676745511456" rpy="0 0 0"/>
    <mass value="0.5633553038394754"/>
    <inertia ixx="0.000282" iyy="0.000391" izz="0.000203" ixy="-1.2e-05" iyz="1.7e-05" ixz="0.00015"/>
  </inertial>
  <visual>
    <origin xyz="-0.092849 -0.015305 -0.104202" rpy="0 0 0"/>
    <geometry>
      <mesh filename="package://twodofrobotarm_description/meshes/end_effector_v2_1.stl" scale="0.001 0.001 0.001"/>
    </geometry>
    <material name="steel_satin"/>
  </visual>
  <collision>
    <origin xyz="-0.092849 -0.015305 -0.104202" rpy="0 0 0"/>
    <geometry>
      <mesh filename="package://twodofrobotarm_description/meshes/end_effector_v2_1.stl" scale="0.001 0.001 0.001"/>
    </geometry>
  </collision>
</link>

<joint name="Rev1" type="continuous">
  <origin xyz="0.0 0.0 0.04" rpy="0 0 0"/>
  <parent link="base_link"/>
  <child link="link1_v3_1"/>
  <axis xyz="0.0 0.0 1.0"/>
</joint>

<joint name="Rev2" type="revolute">
  <origin xyz="0.0011 -0.009939 0.03" rpy="0 0 0"/>
  <parent link="link1_v3_1"/>
  <child link="link2_v1_1"/>
  <axis xyz="0.109981 -0.993934 -0.0"/>
  <limit upper="2.443461" lower="0.0" effort="100" velocity="100"/>
</joint>

<joint name="Rev3" type="revolute">
  <origin xyz="0.091749 0.025244 0.034202" rpy="0 0 0"/>
  <parent link="link2_v1_1"/>
  <child link="end_effector_v2_1"/>
  <axis xyz="-0.109981 0.993934 -0.0"/>
  <limit upper="6.283185" lower="3.141593" effort="100" velocity="100"/>
</joint>

</robot>
